<?xml version="1.0" ?>
<robot name="stubby_complete" xmlns:xacro="http://www.ros.org/wiki/xacro">

<xacro:include filename="$(find stubby_complete_description)/urdf/materials.xacro" />
<xacro:include filename="$(find stubby_complete_description)/urdf/stubby_complete.trans" />
<xacro:include filename="$(find stubby_complete_description)/urdf/stubby_complete.gazebo" />
<link name="base_link">
  <inertial>
    <origin rpy="0 0 0" xyz="-0.09999999999999991 -0.020966127283006095 0.021818497006580385"/>
    <mass value="2.9547595128701887"/>
    <inertia ixx="0.021203" ixy="-0.0" ixz="-0.0" iyy="0.010579" iyz="-6.5e-05" izz="0.030287"/>
  </inertial>
  <visual>
    <origin rpy="0 0 0" xyz="0 0 0"/>
    <geometry>
      <mesh filename="package://stubby_complete_description/meshes/base_link.stl" scale="0.001 0.001 0.001"/>
    </geometry>
    <material name="silver"/>
  </visual>
  <collision>
    <origin rpy="0 0 0" xyz="0 0 0"/>
    <geometry>
      <mesh filename="package://stubby_complete_description/meshes/base_link.stl" scale="0.001 0.001 0.001"/>
    </geometry>
  </collision>
</link>

<link name="Component1_1">
  <inertial>
    <origin rpy="0 0 0" xyz="-0.04000000000451927 -0.03980214384253428 0.008090034598972902"/>
    <mass value="0.4759246467338889"/>
    <inertia ixx="0.000408" ixy="0.0" ixz="0.0" iyy="0.000441" iyz="-0.0" izz="0.000831"/>
  </inertial>
  <visual>
    <origin rpy="0 0 0" xyz="0.06 0.026523 -0.045914"/>
    <geometry>
      <mesh filename="package://stubby_complete_description/meshes/Component1_1.stl" scale="0.001 0.001 0.001"/>
    </geometry>
    <material name="silver"/>
  </visual>
  <collision>
    <origin rpy="0 0 0" xyz="0.06 0.026523 -0.045914"/>
    <geometry>
      <mesh filename="package://stubby_complete_description/meshes/Component1_1.stl" scale="0.001 0.001 0.001"/>
    </geometry>
  </collision>
</link>

<link name="Component2_1">
  <inertial>
    <origin rpy="0 0 0" xyz="-3.1092385663913924e-05 -0.012761856959488546 0.017058190511466446"/>
    <mass value="0.04244091097100989"/>
    <inertia ixx="1.2e-05" ixy="-0.0" ixz="0.0" iyy="7e-06" iyz="-0.0" izz="1e-05"/>
  </inertial>
  <visual>
    <origin rpy="0 0 0" xyz="0.1 0.052023 -0.060914"/>
    <geometry>
      <mesh filename="package://stubby_complete_description/meshes/Component2_1.stl" scale="0.001 0.001 0.001"/>
    </geometry>
    <material name="silver"/>
  </visual>
  <collision>
    <origin rpy="0 0 0" xyz="0.1 0.052023 -0.060914"/>
    <geometry>
      <mesh filename="package://stubby_complete_description/meshes/Component2_1.stl" scale="0.001 0.001 0.001"/>
    </geometry>
  </collision>
</link>

<link name="Component3_1">
  <inertial>
    <origin rpy="0 0 0" xyz="-3.2040751634265785e-05 4.2101147429418617e-07 0.002337181396787208"/>
    <mass value="0.02417691266422109"/>
    <inertia ixx="1e-06" ixy="-0.0" ixz="-0.0" iyy="4e-06" iyz="-0.0" izz="5e-06"/>
  </inertial>
  <visual>
    <origin rpy="0 0 0" xyz="0.1 0.052023 -0.097914"/>
    <geometry>
      <mesh filename="package://stubby_complete_description/meshes/Component3_1.stl" scale="0.001 0.001 0.001"/>
    </geometry>
    <material name="silver"/>
  </visual>
  <collision>
    <origin rpy="0 0 0" xyz="0.1 0.052023 -0.097914"/>
    <geometry>
      <mesh filename="package://stubby_complete_description/meshes/Component3_1.stl" scale="0.001 0.001 0.001"/>
    </geometry>
  </collision>
</link>

<link name="Component4_1">
  <inertial>
    <origin rpy="0 0 0" xyz="-0.01494141726061049 -0.006261856959488575 0.013530700157741146"/>
    <mass value="0.04244091097100989"/>
    <inertia ixx="1e-05" ixy="-0.0" ixz="-0.0" iyy="7e-06" iyz="0.0" izz="1.2e-05"/>
  </inertial>
  <visual>
    <origin rpy="0 0 0" xyz="0.084 0.044023 -0.103414"/>
    <geometry>
      <mesh filename="package://stubby_complete_description/meshes/Component4_1.stl" scale="0.001 0.001 0.001"/>
    </geometry>
    <material name="silver"/>
  </visual>
  <collision>
    <origin rpy="0 0 0" xyz="0.084 0.044023 -0.103414"/>
    <geometry>
      <mesh filename="package://stubby_complete_description/meshes/Component4_1.stl" scale="0.001 0.001 0.001"/>
    </geometry>
  </collision>
</link>

<link name="Component5_1">
  <inertial>
    <origin rpy="0 0 0" xyz="0.000323439859071295 0.044213030801076594 1.0167311355765984e-05"/>
    <mass value="0.07320231395363634"/>
    <inertia ixx="8e-05" ixy="4e-06" ixz="0.0" iyy="6e-06" iyz="-0.0" izz="7.5e-05"/>
  </inertial>
  <visual>
    <origin rpy="0 0 0" xyz="0.079 0.037523 -0.116914"/>
    <geometry>
      <mesh filename="package://stubby_complete_description/meshes/Component5_1.stl" scale="0.001 0.001 0.001"/>
    </geometry>
    <material name="silver"/>
  </visual>
  <collision>
    <origin rpy="0 0 0" xyz="0.079 0.037523 -0.116914"/>
    <geometry>
      <mesh filename="package://stubby_complete_description/meshes/Component5_1.stl" scale="0.001 0.001 0.001"/>
    </geometry>
  </collision>
</link>

<link name="Component6_1">
  <inertial>
    <origin rpy="0 0 0" xyz="-0.01494141726061049 0.01773814304051132 -0.013469299842258711"/>
    <mass value="0.04244091097100989"/>
    <inertia ixx="1e-05" ixy="-0.0" ixz="-0.0" iyy="7e-06" iyz="0.0" izz="1.2e-05"/>
  </inertial>
  <visual>
    <origin rpy="0 0 0" xyz="0.084 -0.051977 -0.130414"/>
    <geometry>
      <mesh filename="package://stubby_complete_description/meshes/Component6_1.stl" scale="0.001 0.001 0.001"/>
    </geometry>
    <material name="silver"/>
  </visual>
  <collision>
    <origin rpy="0 0 0" xyz="0.084 -0.051977 -0.130414"/>
    <geometry>
      <mesh filename="package://stubby_complete_description/meshes/Component6_1.stl" scale="0.001 0.001 0.001"/>
    </geometry>
  </collision>
</link>

<link name="Component7_1">
  <inertial>
    <origin rpy="0 0 0" xyz="-0.003787166400802497 -0.03908271518949953 -0.013398484021248727"/>
    <mass value="0.05604795467246254"/>
    <inertia ixx="4.5e-05" ixy="-1e-06" ixz="-0.0" iyy="4e-06" iyz="-0.0" izz="4.1e-05"/>
  </inertial>
  <visual>
    <origin rpy="0 0 0" xyz="0.116 -0.051977 -0.130414"/>
    <geometry>
      <mesh filename="package://stubby_complete_description/meshes/Component7_1.stl" scale="0.001 0.001 0.001"/>
    </geometry>
    <material name="silver"/>
  </visual>
  <collision>
    <origin rpy="0 0 0" xyz="0.116 -0.051977 -0.130414"/>
    <geometry>
      <mesh filename="package://stubby_complete_description/meshes/Component7_1.stl" scale="0.001 0.001 0.001"/>
    </geometry>
  </collision>
</link>

<link name="Component8_1">
  <inertial>
    <origin rpy="0 0 0" xyz="0.00032343985907133666 0.04421303080107655 1.0167311355960273e-05"/>
    <mass value="0.07320231395363634"/>
    <inertia ixx="8e-05" ixy="4e-06" ixz="0.0" iyy="6e-06" iyz="-0.0" izz="7.5e-05"/>
  </inertial>
  <visual>
    <origin rpy="0 0 0" xyz="0.079 -0.082477 -0.116914"/>
    <geometry>
      <mesh filename="package://stubby_complete_description/meshes/Component8_1.stl" scale="0.001 0.001 0.001"/>
    </geometry>
    <material name="silver"/>
  </visual>
  <collision>
    <origin rpy="0 0 0" xyz="0.079 -0.082477 -0.116914"/>
    <geometry>
      <mesh filename="package://stubby_complete_description/meshes/Component8_1.stl" scale="0.001 0.001 0.001"/>
    </geometry>
  </collision>
</link>

<link name="Component9_1">
  <inertial>
    <origin rpy="0 0 0" xyz="-0.014941417260610448 0.017738143040511356 -0.01346929984225867"/>
    <mass value="0.04244091097100989"/>
    <inertia ixx="1e-05" ixy="-0.0" ixz="-0.0" iyy="7e-06" iyz="0.0" izz="1.2e-05"/>
  </inertial>
  <visual>
    <origin rpy="0 0 0" xyz="0.084 -0.171977 -0.130414"/>
    <geometry>
      <mesh filename="package://stubby_complete_description/meshes/Component9_1.stl" scale="0.001 0.001 0.001"/>
    </geometry>
    <material name="silver"/>
  </visual>
  <collision>
    <origin rpy="0 0 0" xyz="0.084 -0.171977 -0.130414"/>
    <geometry>
      <mesh filename="package://stubby_complete_description/meshes/Component9_1.stl" scale="0.001 0.001 0.001"/>
    </geometry>
  </collision>
</link>

<link name="Component10_1">
  <inertial>
    <origin rpy="0 0 0" xyz="-0.0037871664008025108 -0.03908271518949957 -0.013398484021248672"/>
    <mass value="0.05604795467246254"/>
    <inertia ixx="4.5e-05" ixy="-1e-06" ixz="-0.0" iyy="4e-06" iyz="-0.0" izz="4.1e-05"/>
  </inertial>
  <visual>
    <origin rpy="0 0 0" xyz="0.116 -0.171977 -0.130414"/>
    <geometry>
      <mesh filename="package://stubby_complete_description/meshes/Component10_1.stl" scale="0.001 0.001 0.001"/>
    </geometry>
    <material name="silver"/>
  </visual>
  <collision>
    <origin rpy="0 0 0" xyz="0.116 -0.171977 -0.130414"/>
    <geometry>
      <mesh filename="package://stubby_complete_description/meshes/Component10_1.stl" scale="0.001 0.001 0.001"/>
    </geometry>
  </collision>
</link>

<link name="Component11_1">
  <inertial>
    <origin rpy="0 0 0" xyz="-0.021096269692649494 0.02403068850135351 -0.0008093901396380859"/>
    <mass value="0.13274101174114958"/>
    <inertia ixx="4e-05" ixy="-0.0" ixz="0.0" iyy="7.2e-05" iyz="1e-06" izz="9.3e-05"/>
  </inertial>
  <visual>
    <origin rpy="0 0 0" xyz="0.079 -0.202477 -0.116914"/>
    <geometry>
      <mesh filename="package://stubby_complete_description/meshes/Component11_1.stl" scale="0.001 0.001 0.001"/>
    </geometry>
    <material name="silver"/>
  </visual>
  <collision>
    <origin rpy="0 0 0" xyz="0.079 -0.202477 -0.116914"/>
    <geometry>
      <mesh filename="package://stubby_complete_description/meshes/Component11_1.stl" scale="0.001 0.001 0.001"/>
    </geometry>
  </collision>
</link>

<link name="Component12_1">
  <inertial>
    <origin rpy="0 0 0" xyz="0.012000002645184221 0.013803147559605988 0.009796072677114534"/>
    <mass value="0.24061936425261632"/>
    <inertia ixx="8.2e-05" ixy="0.0" ixz="0.0" iyy="0.00037" iyz="-1e-06" izz="0.000359"/>
  </inertial>
  <visual>
    <origin rpy="0 0 0" xyz="0.112 -0.244477 -0.106914"/>
    <geometry>
      <mesh filename="package://stubby_complete_description/meshes/Component12_1.stl" scale="0.001 0.001 0.001"/>
    </geometry>
    <material name="silver"/>
  </visual>
  <collision>
    <origin rpy="0 0 0" xyz="0.112 -0.244477 -0.106914"/>
    <geometry>
      <mesh filename="package://stubby_complete_description/meshes/Component12_1.stl" scale="0.001 0.001 0.001"/>
    </geometry>
  </collision>
</link>

<link name="Component13_1">
  <inertial>
    <origin rpy="0 0 0" xyz="-0.005999999999999797 4.2101146963124947e-07 -0.010000392072206168"/>
    <mass value="0.03388498185890325"/>
    <inertia ixx="4e-06" ixy="0.0" ixz="0.0" iyy="4e-06" iyz="0.0" izz="1e-06"/>
  </inertial>
  <visual>
    <origin rpy="0 0 0" xyz="0.061 -0.273777 -0.126914"/>
    <geometry>
      <mesh filename="package://stubby_complete_description/meshes/Component13_1.stl" scale="0.001 0.001 0.001"/>
    </geometry>
    <material name="silver"/>
  </visual>
  <collision>
    <origin rpy="0 0 0" xyz="0.061 -0.273777 -0.126914"/>
    <geometry>
      <mesh filename="package://stubby_complete_description/meshes/Component13_1.stl" scale="0.001 0.001 0.001"/>
    </geometry>
  </collision>
</link>

<link name="Component14_1">
  <inertial>
    <origin rpy="0 0 0" xyz="0.006000000000000255 4.2101146963124947e-07 -0.010000392072206238"/>
    <mass value="0.03388498185890325"/>
    <inertia ixx="4e-06" ixy="0.0" ixz="-0.0" iyy="4e-06" iyz="0.0" izz="1e-06"/>
  </inertial>
  <visual>
    <origin rpy="0 0 0" xyz="0.139 -0.273777 -0.126914"/>
    <geometry>
      <mesh filename="package://stubby_complete_description/meshes/Component14_1.stl" scale="0.001 0.001 0.001"/>
    </geometry>
    <material name="silver"/>
  </visual>
  <collision>
    <origin rpy="0 0 0" xyz="0.139 -0.273777 -0.126914"/>
    <geometry>
      <mesh filename="package://stubby_complete_description/meshes/Component14_1.stl" scale="0.001 0.001 0.001"/>
    </geometry>
  </collision>
</link>

<link name="Component15_1">
  <inertial>
    <origin rpy="0 0 0" xyz="0.0009965764718817827 0.020031481883907132 -3.9222792255766414e-07"/>
    <mass value="0.047142162662326015"/>
    <inertia ixx="1.1e-05" ixy="0.0" ixz="0.0" iyy="4e-06" iyz="0.0" izz="8e-06"/>
  </inertial>
  <visual>
    <origin rpy="0 0 0" xyz="0.133 -0.280277 -0.116914"/>
    <geometry>
      <mesh filename="package://stubby_complete_description/meshes/Component15_1.stl" scale="0.001 0.001 0.001"/>
    </geometry>
    <material name="silver"/>
  </visual>
  <collision>
    <origin rpy="0 0 0" xyz="0.133 -0.280277 -0.116914"/>
    <geometry>
      <mesh filename="package://stubby_complete_description/meshes/Component15_1.stl" scale="0.001 0.001 0.001"/>
    </geometry>
  </collision>
</link>

<link name="Component16_1">
  <inertial>
    <origin rpy="0 0 0" xyz="-0.0009965764718812414 0.020031481883907132 -3.9222792257154193e-07"/>
    <mass value="0.047142162662326015"/>
    <inertia ixx="1.1e-05" ixy="-0.0" ixz="-0.0" iyy="4e-06" iyz="-0.0" izz="8e-06"/>
  </inertial>
  <visual>
    <origin rpy="0 0 0" xyz="0.067 -0.280277 -0.116914"/>
    <geometry>
      <mesh filename="package://stubby_complete_description/meshes/Component16_1.stl" scale="0.001 0.001 0.001"/>
    </geometry>
    <material name="silver"/>
  </visual>
  <collision>
    <origin rpy="0 0 0" xyz="0.067 -0.280277 -0.116914"/>
    <geometry>
      <mesh filename="package://stubby_complete_description/meshes/Component16_1.stl" scale="0.001 0.001 0.001"/>
    </geometry>
  </collision>
</link>

<link name="Component17_1">
  <inertial>
    <origin rpy="0 0 0" xyz="-1.734723475976807e-15 0.00020255311593160574 0.004993320817949488"/>
    <mass value="0.4507941946898463"/>
    <inertia ixx="0.001622" ixy="-0.0" ixz="0.0" iyy="0.001632" iyz="-0.0" izz="0.003247"/>
  </inertial>
  <visual>
    <origin rpy="0 0 0" xyz="0.1 -0.123477 -0.045914"/>
    <geometry>
      <mesh filename="package://stubby_complete_description/meshes/Component17_1.stl" scale="0.001 0.001 0.001"/>
    </geometry>
    <material name="silver"/>
  </visual>
  <collision>
    <origin rpy="0 0 0" xyz="0.1 -0.123477 -0.045914"/>
    <geometry>
      <mesh filename="package://stubby_complete_description/meshes/Component17_1.stl" scale="0.001 0.001 0.001"/>
    </geometry>
  </collision>
</link>

<joint name="Rigid1" type="fixed">
  <origin rpy="0 0 0" xyz="-0.06 -0.026523 0.045914"/>
  <parent link="base_link"/>
  <child link="Component1_1"/>
</joint>

<joint name="Rigid2" type="fixed">
  <origin rpy="0 0 0" xyz="-0.04 -0.0255 0.015"/>
  <parent link="Component1_1"/>
  <child link="Component2_1"/>
</joint>

<joint name="yaw" type="continuous">
  <origin rpy="0 0 0" xyz="0.0 0.0 0.037"/>
  <parent link="Component2_1"/>
  <child link="Component3_1"/>
  <axis xyz="0.0 -0.0 1.0"/>
</joint>

<joint name="Rigid4" type="fixed">
  <origin rpy="0 0 0" xyz="0.016 0.008 0.0055"/>
  <parent link="Component3_1"/>
  <child link="Component4_1"/>
</joint>

<joint name="Rev1" type="continuous">
  <origin rpy="0 0 0" xyz="0.005 0.0065 0.0135"/>
  <parent link="Component4_1"/>
  <child link="Component5_1"/>
  <axis xyz="1.0 -0.0 0.0"/>
</joint>

<joint name="Rigid6" type="fixed">
  <origin rpy="0 0 0" xyz="-0.005 0.0895 0.0135"/>
  <parent link="Component5_1"/>
  <child link="Component6_1"/>
</joint>

<joint name="Rigid7" type="fixed">
  <origin rpy="0 0 0" xyz="-0.032 0.0 0.0"/>
  <parent link="Component6_1"/>
  <child link="Component7_1"/>
</joint>

<joint name="Rev2" type="continuous">
  <origin rpy="0 0 0" xyz="0.005 0.0305 -0.0135"/>
  <parent link="Component6_1"/>
  <child link="Component8_1"/>
  <axis xyz="1.0 -0.0 0.0"/>
</joint>

<joint name="Rigid9" type="fixed">
  <origin rpy="0 0 0" xyz="-0.005 0.0895 0.0135"/>
  <parent link="Component8_1"/>
  <child link="Component9_1"/>
</joint>

<joint name="Rigid10" type="fixed">
  <origin rpy="0 0 0" xyz="-0.032 0.0 0.0"/>
  <parent link="Component9_1"/>
  <child link="Component10_1"/>
</joint>

<joint name="gripAngle" type="continuous">
  <origin rpy="0 0 0" xyz="0.005 0.0305 -0.0135"/>
  <parent link="Component9_1"/>
  <child link="Component11_1"/>
  <axis xyz="1.0 -0.0 0.0"/>
</joint>

<joint name="Rigid12" type="fixed">
  <origin rpy="0 0 0" xyz="-0.033 0.042 -0.01"/>
  <parent link="Component11_1"/>
  <child link="Component12_1"/>
</joint>

<joint name="Rigid13" type="fixed">
  <origin rpy="0 0 0" xyz="0.051 0.0293 0.02"/>
  <parent link="Component12_1"/>
  <child link="Component13_1"/>
</joint>

<joint name="Rigid14" type="fixed">
  <origin rpy="0 0 0" xyz="-0.027 0.0293 0.02"/>
  <parent link="Component12_1"/>
  <child link="Component14_1"/>
</joint>

<joint name="Rigid15" type="fixed">
  <origin rpy="0 0 0" xyz="0.006 0.0065 -0.01"/>
  <parent link="Component14_1"/>
  <child link="Component15_1"/>
</joint>

<joint name="Rigid16" type="fixed">
  <origin rpy="0 0 0" xyz="-0.006 0.0065 -0.01"/>
  <parent link="Component13_1"/>
  <child link="Component16_1"/>
</joint>

<joint name="platformAngle" type="continuous">
  <origin rpy="0 0 0" xyz="-0.1 0.123477 0.045914"/>
  <parent link="base_link"/>
  <child link="Component17_1"/>
  <axis xyz="0.0 -0.0 1.0"/>
</joint>

</robot>
