<?xml version="1.0" ?>
<robot name="stubby" xmlns:xacro="http://www.ros.org/wiki/xacro">

<xacro:include filename="$(find stubby_description)/urdf/materials.xacro" />
<xacro:include filename="$(find stubby_description)/urdf/stubby.trans" />
<xacro:include filename="$(find stubby_description)/urdf/stubby.gazebo" />
<link name="base_link">
  <inertial>
    <origin rpy="0 0 0" xyz="-0.1 -0.020955069490217113 0.026811359768947437"/>
    <mass value="2.9540424862254815"/>
    <inertia ixx="0.021201" ixy="0.0" ixz="-0.0" iyy="0.010579" iyz="-6.6e-05" izz="0.030285"/>
  </inertial>
  <visual>
    <origin rpy="0 0 0" xyz="0 0 0"/>
    <geometry>
      <mesh filename="package://stubby_description/meshes/base_link.stl" scale="0.001 0.001 0.001"/>
    </geometry>
    <material name="silver"/>
  </visual>
  <collision>
    <origin rpy="0 0 0" xyz="0 0 0"/>
    <geometry>
      <mesh filename="package://stubby_description/meshes/base_link.stl" scale="0.001 0.001 0.001"/>
    </geometry>
  </collision>
</link>

<link name="Component1_1">
  <inertial>
    <origin rpy="0 0 0" xyz="-3.1092385664038824e-05 -0.012761856959492758 0.01915819051146462"/>
    <mass value="0.04244091097100989"/>
    <inertia ixx="1.2e-05" ixy="-0.0" ixz="0.0" iyy="7e-06" iyz="-0.0" izz="1e-05"/>
  </inertial>
  <visual>
    <origin rpy="0 0 0" xyz="0.1 0.056523 -0.057914"/>
    <geometry>
      <mesh filename="package://stubby_description/meshes/Component1_1.stl" scale="0.001 0.001 0.001"/>
    </geometry>
    <material name="silver"/>
  </visual>
  <collision>
    <origin rpy="0 0 0" xyz="0.1 0.056523 -0.057914"/>
    <geometry>
      <mesh filename="package://stubby_description/meshes/Component1_1.stl" scale="0.001 0.001 0.001"/>
    </geometry>
  </collision>
</link>

<link name="Component2_1">
  <inertial>
    <origin rpy="0 0 0" xyz="-3.2040751634446196e-05 4.210114693675715e-07 0.0023371813967857508"/>
    <mass value="0.02417691266422109"/>
    <inertia ixx="1e-06" ixy="-0.0" ixz="-0.0" iyy="4e-06" iyz="-0.0" izz="5e-06"/>
  </inertial>
  <visual>
    <origin rpy="0 0 0" xyz="0.1 0.056523 -0.097014"/>
    <geometry>
      <mesh filename="package://stubby_description/meshes/Component2_1.stl" scale="0.001 0.001 0.001"/>
    </geometry>
    <material name="silver"/>
  </visual>
  <collision>
    <origin rpy="0 0 0" xyz="0.1 0.056523 -0.097014"/>
    <geometry>
      <mesh filename="package://stubby_description/meshes/Component2_1.stl" scale="0.001 0.001 0.001"/>
    </geometry>
  </collision>
</link>

<link name="Component3_1">
  <inertial>
    <origin rpy="0 0 0" xyz="-0.014941417260610698 0.0017381430405060128 0.013530700157739897"/>
    <mass value="0.04244091097100989"/>
    <inertia ixx="1e-05" ixy="-0.0" ixz="-0.0" iyy="7e-06" iyz="0.0" izz="1.2e-05"/>
  </inertial>
  <visual>
    <origin rpy="0 0 0" xyz="0.084 0.056523 -0.102514"/>
    <geometry>
      <mesh filename="package://stubby_description/meshes/Component3_1.stl" scale="0.001 0.001 0.001"/>
    </geometry>
    <material name="silver"/>
  </visual>
  <collision>
    <origin rpy="0 0 0" xyz="0.084 0.056523 -0.102514"/>
    <geometry>
      <mesh filename="package://stubby_description/meshes/Component3_1.stl" scale="0.001 0.001 0.001"/>
    </geometry>
  </collision>
</link>

<link name="Component4_1">
  <inertial>
    <origin rpy="0 0 0" xyz="0.0005044606380081723 0.054201474348242705 8.501678394876033e-06"/>
    <mass value="0.0869111581488203"/>
    <inertia ixx="0.000129" ixy="4e-06" ixz="0.0" iyy="7e-06" iyz="-0.0" izz="0.000122"/>
  </inertial>
  <visual>
    <origin rpy="0 0 0" xyz="0.079 0.042023 -0.116014"/>
    <geometry>
      <mesh filename="package://stubby_description/meshes/Component4_1.stl" scale="0.001 0.001 0.001"/>
    </geometry>
    <material name="silver"/>
  </visual>
  <collision>
    <origin rpy="0 0 0" xyz="0.079 0.042023 -0.116014"/>
    <geometry>
      <mesh filename="package://stubby_description/meshes/Component4_1.stl" scale="0.001 0.001 0.001"/>
    </geometry>
  </collision>
</link>

<link name="Component5_1">
  <inertial>
    <origin rpy="0 0 0" xyz="-0.014941417260610629 0.017738143040505916 -0.013469299842255589"/>
    <mass value="0.04244091097100989"/>
    <inertia ixx="1e-05" ixy="-0.0" ixz="-0.0" iyy="7e-06" iyz="0.0" izz="1.2e-05"/>
  </inertial>
  <visual>
    <origin rpy="0 0 0" xyz="0.084 -0.067477 -0.129514"/>
    <geometry>
      <mesh filename="package://stubby_description/meshes/Component5_1.stl" scale="0.001 0.001 0.001"/>
    </geometry>
    <material name="silver"/>
  </visual>
  <collision>
    <origin rpy="0 0 0" xyz="0.084 -0.067477 -0.129514"/>
    <geometry>
      <mesh filename="package://stubby_description/meshes/Component5_1.stl" scale="0.001 0.001 0.001"/>
    </geometry>
  </collision>
</link>

<link name="Component6_1">
  <inertial>
    <origin rpy="0 0 0" xyz="0.0005044606380081446 0.05420147434824256 8.501678399372437e-06"/>
    <mass value="0.0869111581488203"/>
    <inertia ixx="0.000129" ixy="4e-06" ixz="0.0" iyy="7e-06" iyz="-0.0" izz="0.000122"/>
  </inertial>
  <visual>
    <origin rpy="0 0 0" xyz="0.079 -0.097977 -0.116014"/>
    <geometry>
      <mesh filename="package://stubby_description/meshes/Component6_1.stl" scale="0.001 0.001 0.001"/>
    </geometry>
    <material name="silver"/>
  </visual>
  <collision>
    <origin rpy="0 0 0" xyz="0.079 -0.097977 -0.116014"/>
    <geometry>
      <mesh filename="package://stubby_description/meshes/Component6_1.stl" scale="0.001 0.001 0.001"/>
    </geometry>
  </collision>
</link>

<link name="base1_1">
  <inertial>
    <origin rpy="0 0 0" xyz="-3.397215732725556e-06 5.502213756908292e-05 0.00496061605955591"/>
    <mass value="0.4968646843052766"/>
    <inertia ixx="0.000271" ixy="-0.0" ixz="0.0" iyy="0.000272" iyz="-0.0" izz="0.000534"/>
  </inertial>
  <visual>
    <origin rpy="0 0 0" xyz="0.1 0.066523 -0.050914"/>
    <geometry>
      <mesh filename="package://stubby_description/meshes/base1_1.stl" scale="0.001 0.001 0.001"/>
    </geometry>
    <material name="silver"/>
  </visual>
  <collision>
    <origin rpy="0 0 0" xyz="0.1 0.066523 -0.050914"/>
    <geometry>
      <mesh filename="package://stubby_description/meshes/base1_1.stl" scale="0.001 0.001 0.001"/>
    </geometry>
  </collision>
</link>

<joint name="Rigid1" type="fixed">
  <origin rpy="0 0 0" xyz="0.0 0.01 0.007"/>
  <parent link="base1_1"/>
  <child link="Component1_1"/>
</joint>

<joint name="Rev1" type="continuous">
  <origin rpy="0 0 0" xyz="0.0 0.0 0.0391"/>
  <parent link="Component1_1"/>
  <child link="Component2_1"/>
  <axis xyz="-0.0 -0.0 1.0"/>
</joint>

<joint name="Rigid3" type="fixed">
  <origin rpy="0 0 0" xyz="0.016 0.0 0.0055"/>
  <parent link="Component2_1"/>
  <child link="Component3_1"/>
</joint>

<joint name="Rev2" type="continuous">
  <origin rpy="0 0 0" xyz="0.005 0.0145 0.0135"/>
  <parent link="Component3_1"/>
  <child link="Component4_1"/>
  <axis xyz="1.0 -0.0 0.0"/>
</joint>

<joint name="Rigid5" type="fixed">
  <origin rpy="0 0 0" xyz="-0.005 0.1095 0.0135"/>
  <parent link="Component4_1"/>
  <child link="Component5_1"/>
</joint>

<joint name="Rev3" type="continuous">
  <origin rpy="0 0 0" xyz="0.005 0.0305 -0.0135"/>
  <parent link="Component5_1"/>
  <child link="Component6_1"/>
  <axis xyz="1.0 -0.0 0.0"/>
</joint>

<joint name="Rigid7" type="fixed">
  <origin rpy="0 0 0" xyz="-0.1 -0.066523 0.050914"/>
  <parent link="base_link"/>
  <child link="base1_1"/>
</joint>

</robot>
